Workbook

Sheet Results
A1: WXPN app device tests | C1: Current iPhone 1 | D1: Current iPhone 2 | E1: Older iPhone (iOS 16/17) | F1: iPad | G1: Pixel | H1: Samsung | I1: Notes
B2: OS version
B3: App build
B4: Tester
B5: Date
A7: Area | B7: Check | C7: Current iPhone 1 | D7: Current iPhone 2 | E7: Older iPhone (iOS 16/17) | F7: iPad | G7: Pixel | H7: Samsung | I7: Notes and issue links
A8: Listening | B8: WXPN plays within a few seconds of Listen live; XPN2 and Homegrown too.
A9: Listening | B9: Lock the phone: audio carries on, and the lock screen shows the song, its artwork and play/pause, which work.
A10: Listening | B10: Switch to another app for a few minutes, come back: still playing, song info current.
A11: Listening | B11: Headphones: unplug (or disconnect Bluetooth) pauses; the headset button plays and pauses.
A12: Listening | B12: A phone call, or another app's audio, pauses the station; it doesn't fight back.
A13: Listening | B13: Airplane mode while playing: "Reconnecting", then it plays again within seconds of turning airplane mode off.
A14: Listening | B14: iPhone: the ring/silent switch on silent still plays the station. | G14: N/A | H14: N/A
A15: Listening | B15: AirPlay (iPhone) to a speaker or TV, from the mini player and Listen. | G15: N/A | H15: N/A
A16: Listening | B16: Sleep timer, 15 minutes: fades out and stops.
A17: Archive | B17: Tap an episode in Shows › Archive: it plays, its row is tinted; tap it again: it pauses. Skip back 15 and ahead 30; the lock screen shows the episode with skip and the scrubber.
A18: Archive | B18: Pause, close the app fully, reopen: the episode resumes where it was.
A19: Archive | B19: Save an episode, wait an hour, play it from Favorites: it plays (the link is read again).
A20: Notifications | B20: Turn on show reminders for a show starting within the hour: the permission prompt appears once; the reminder arrives with the app closed, and tapping it opens Listen playing WXPN.
A21: Notifications | B21: Radio alarm for two minutes from now, app closed and phone locked: it arrives on time; tapping starts the wake-up station at the alarm volume. Android 14+: the prompt to allow Alarms & reminders appears when the alarm is turned on.
A22: Notifications | B22: The alarm keeps ringing with the app left closed: set it for a time a few minutes ahead on today's weekday, let it ring, then (without opening the app) move the phone's clock a week on, or leave it two weeks; it rings each week. On Android, with the phone left idle and unplugged overnight, the next week's alarm is still on time.
A23: Notifications | B23: An alarm set for under a minute from now still rings.
A24: Notifications | B24: Turn notifications off for WXPN in the phone's Settings, reopen the app: reminders and the alarm switch themselves off and say why.
A25: Notifications | B25: Android: the notification icon is the station icon, not a square. | C25: N/A | D25: N/A | E25: N/A | F25: N/A
A26: Links and sign-ins | B26: Tap an xpn.org show link (in Messages or Notes): it opens that show's page in the app (needs the files in `native/well-known` hosted on xpn.org).
A27: Links and sign-ins | B27: Share a show from its page; tap the shared link on another phone with the app.
A28: Links and sign-ins | B28: Settings › Your playlist › Apple Music (and Spotify, if set up): the sign-in completes and returns to the app; heart a song, and it shows in "WXPN Favorites" there.
A29: Links and sign-ins | B29: Donate opens xpn.org in the in-app browser; closing it returns to the app.
A30: Videos and concerts | B30: A World Cafe video plays in the app, full screen and back; the radio pauses and is offered back afterwards.
A31: Videos and concerts | B31: iPhone: a live YouTube video (Free at Noon) opens in the in-app browser. | G31: N/A | H31: N/A
A32: Videos and concerts | B32: Open a concert, Add to calendar: the system's New Event sheet opens, filled in; it saves to the calendar.
A33: Videos and concerts | B33: Open a song's sheet, Open in Spotify and Open in Apple Music: with the app installed, it opens on the search for the song (not the web page); without it, the browser does.
A34: The car | B34: CarPlay (Xcode's CarPlay simulator, then a car): WXPN, XPN2 and Homegrown are listed, each with its orange tile; choosing one plays it and opens Now Playing, with the song, artist and artwork, and play and pause only (no skip, no scrubber: it's live). | G34: N/A | H34: N/A
A35: The car | B35: CarPlay: back to the list, the playing station is marked; choose another and it switches; choose the same one while Now Playing shows and nothing breaks. | G35: N/A | H35: N/A
A36: The car | B36: CarPlay, cold: force-quit the phone app, connect, choose a station. It must play with the phone locked. (The web view runs without a window then; if it doesn't play, this is the first thing to fix.) | G36: N/A | H36: N/A
A37: The car | B37: CarPlay: connect while a station is already playing on the phone; the list marks it straight away. | G37: N/A | H37: N/A
A38: The car | B38: CarPlay: a phone call, then Siri, then a navigation prompt during play; the station ducks or pauses and comes back. | G38: N/A | H38: N/A
A39: The car | B39: CarPlay: no signal (airplane mode mid-play); the app recovers when signal returns, and the car doesn't show a stuck spinner. | G39: N/A | H39: N/A
A40: The car | B40: Android Auto (the Desktop Head Unit, then a car): the same list with tiles; Now Playing shows the song's artwork (the station's tile until it loads); play and pause from the car and the steering wheel; start from the car with the phone app closed. | C40: N/A | D40: N/A | E40: N/A | F40: N/A
A41: Home screen widget | B41: Add it (iPhone: long press the home screen › + › WXPN, small, medium and large; Android: long press › Widgets › WXPN). Before the app has played anything it shows WXPN and the station's tile.
...

Sheet Summary
A1: Device | B1: Pass | C1: Fail | D1: Blocked | E1: N/A | F1: Not run
A2: Current iPhone 1 | B2: =COUNTIF(Results!C7:C59,"Pass") | C2: =COUNTIF(Results!C7:C59,"Fail") | D2: =COUNTIF(Results!C7:C59,"Blocked") | E2: =COUNTIF(Results!C7:C59,"N/A") | F2: =COUNTBLANK(Results!C7:C59)
A3: Current iPhone 2 | B3: =COUNTIF(Results!D7:D59,"Pass") | C3: =COUNTIF(Results!D7:D59,"Fail") | D3: =COUNTIF(Results!D7:D59,"Blocked") | E3: =COUNTIF(Results!D7:D59,"N/A") | F3: =COUNTBLANK(Results!D7:D59)
A4: Older iPhone (iOS 16/17) | B4: =COUNTIF(Results!E7:E59,"Pass") | C4: =COUNTIF(Results!E7:E59,"Fail") | D4: =COUNTIF(Results!E7:E59,"Blocked") | E4: =COUNTIF(Results!E7:E59,"N/A") | F4: =COUNTBLANK(Results!E7:E59)
A5: iPad | B5: =COUNTIF(Results!F7:F59,"Pass") | C5: =COUNTIF(Results!F7:F59,"Fail") | D5: =COUNTIF(Results!F7:F59,"Blocked") | E5: =COUNTIF(Results!F7:F59,"N/A") | F5: =COUNTBLANK(Results!F7:F59)
A6: Pixel | B6: =COUNTIF(Results!G7:G59,"Pass") | C6: =COUNTIF(Results!G7:G59,"Fail") | D6: =COUNTIF(Results!G7:G59,"Blocked") | E6: =COUNTIF(Results!G7:G59,"N/A") | F6: =COUNTBLANK(Results!G7:G59)
A7: Samsung | B7: =COUNTIF(Results!H7:H59,"Pass") | C7: =COUNTIF(Results!H7:H59,"Fail") | D7: =COUNTIF(Results!H7:H59,"Blocked") | E7: =COUNTIF(Results!H7:H59,"N/A") | F7: =COUNTBLANK(Results!H7:H59)
